src/game-data/eras/napoleonic/scenarios/austerlitz.json
{"version":1,"startTime":"07:30","maxTurn":40,"name":"name","description":"description","locales":{"en":{"name":"Battle of Austerlitz","description":"The Battle of the Three Emperors, 2 December 1805, from 07:30: Kienmayer is going in at Telnitz, the allied columns are coming down off the Pratzen, and Soult's two divisions are still hidden behind the Goldbach. Davout is not here yet - III Corps marches on from Gross-Raigern at 08:30, the hour it arrived. 12.8 by 12.8 km at 50 m a tile, with the Satschan and Menitz ponds restored and the motorway and railway stripped out. 372 units from Nafziger's orders of battle: 197 battalions, 116 double squadrons and 59 batteries, each named."}},"players":[{"player":1,"team":1,"name":"V Corps (Lannes)","ammoReserve":62500,"baseAmmoReserve":62500},{"player":2,"team":1,"name":"Murat's Light Cavalry","ammoReserve":35000,"baseAmmoReserve":35000},{"player":3,"team":1,"name":"I Corps (Bernadotte)","ammoReserve":37500,"baseAmmoReserve":37500},{"player":4,"team":1,"name":"Imperial Guard","ammoReserve":32500,"baseAmmoReserve":32500},{"player":5,"team":1,"name":"IV Corps (Legrand)","ammoReserve":35000,"baseAmmoReserve":35000},{"player":6,"team":1,"name":"III Corps (Davout)","ammoReserve":10000,"baseAmmoReserve":10000},{"player":7,"team":1,"name":"Murat's Heavy Cavalry","ammoReserve":30000,"baseAmmoReserve":30000},{"player":8,"team":1,"name":"Grenadiers (Oudinot)","ammoReserve":25000,"baseAmmoReserve":25000},{"player":9,"team":1,"name":"IV Corps (Vandamme)","ammoReserve":32500,"baseAmmoReserve":32500},{"player":10,"team":1,"name":"IV Corps (Saint-Hilaire)","ammoReserve":37500,"baseAmmoReserve":37500},{"player":11,"team":2,"name":"Advance Guard (Kienmayer)","ammoReserve":42500,"baseAmmoReserve":42500},{"player":12,"team":2,"name":"1st Column (Dokhturov)","ammoReserve":77500,"baseAmmoReserve":77500},{"player":13,"team":2,"name":"2nd Column (Langeron)","ammoReserve":52500,"baseAmmoReserve":52500},{"player":14,"team":2,"name":"3rd Column (Przybyszewski)","ammoReserve":42500,"baseAmmoReserve":42500},{"player":15,"team":2,"name":"4th Column (Miloradovich)","ammoReserve":57500,"baseAmmoReserve":57500},{"player":16,"team":2,"name":"5th Column (Liechtenstein)","ammoReserve":70000,"baseAmmoReserve":70000},{"player":17,"team":2,"name":"Bagration's Infantry","ammoReserve":45000,"baseAmmoReserve":45000},{"player":18,"team":2,"name":"Reserve, Russian Guard (Constantine)","ammoReserve":60000,"baseAmmoReserve":60000},{"player":19,"team":2,"name":"4th Column (Kollowrat)","ammoReserve":40000,"baseAmmoReserve":40000},{"player":20,"team":2,"name":"Bagration's Cavalry","ammoReserve":67500,"baseAmmoReserve":67500}],"map":{"width":4096,"height":4096,"terrains":[[0,0,0,11,11,11,11,11,11,11,11,11,11,11,11,11,11,11,11,11,11,11,11,11,11,11,3,11,11,11,11,11,11,11,11,11,11,0,0,0,0,0,0,18,18,18,18,18,18,0,0,18,18,18,18,0,18,18,18,18,18,18,18,18,18,18,18,18,18,18,18,18,18,18,18,18,18,18,18,18,18,18,18,18,18,18,18,18,18,18,18,18,18,17,17,17,17,17,17,17,17,17,17,0,0,17,9,17,17,17,17,17,17,17,17,17,17,17,17,17,17,0,0,17,17,17,3,3,17,0,0,0,0,0,17,17,17,17,17,17,17,17,17,17,17,17,17,17,17,17,17,17,17,17,17,17,17,0,0,0,0,0,17,17,17,0,0,17,17,0,0,17,17,17,17,17,17,17,0,0,0,0,19,0,0,0,0,0,0,0,0,11,11,0,0,0,0,4,4,19,19,19,19,19,19,19,19,19,9,19,19,17,17,11,11,11,19,19,19,11,11,11,11,11,11,11,11,11,11,11,11,11,11,11,11,11,11,11,11,11,0,0,0,0,19,0,0,0,0,0,0,0,0,11,11,11],[0,0,0,0,11,11,11,11,11,11,11,11,11,11,11,11,11,11,11,11,11,11,11,11,11,11,3,11,11,11,11,11,11,11,11,11,11,18,18,0,0,0,18,18,18,18,18,18,18,18,0,0,0,0,0,18,18,18,18,18,18,18,18,18,18,18,18,18,18,18,18,18,18,18,18,0,18,18,18,18,18,18,18,18,18,18,18,18,18,18,18,18,18,17,17,17,17,17,17,17,17,17,17,17,17,17,9,17,17,17,17,17,17,17,17,17,17,17,17,17,17,17,17,17,17,17,17,3,3,17,17,0,0,0,17,17,17,17,17,17,17,17,17,17,17,17,17,17,17,17,17,17,17,17,17,17,17,17,17,17,17,17,0,0,17,17,17,17,17,17,17,17,17,17,17,17,0,0,19,19,19,19,19,0,0,0,0,0,0,0,17,17,17,17,17,17,19,4,19,19,19,19,19,19,0,0,0,0,9,0,19,17,17,17,17,19,19,19,11,11,11,11,11,11,11,11,11,11,11,11,11,11,11,11,11,11,11,11,11,11,19,19,19,19,0,0,0,0,0,0,0,0,0,0,11,11],[0,0,0,0,0,0,11,11,11,11,11,11,11,11,11,11,11,11,11,11,11,11,11,11,11,11,3,11,11,11,11,11,11,11,11,0,11,18,18,18,18,18,18,18,18,18,18,18,18,18,18,18,18,18,18,0,18,18,18,18,18,18,18,18,18,18,18,18,18,18,18,18,18,18,18,18,18,18,18,18,18,18,18,18,18,18,18,18,18,18,18,18,18,17,17,17,17,17,17,17,17,17,17,17,17,17,9,17,17,17,17,17,17,17,17,17,17,17,17,17,17,17,17,17,17,17,17,17,3,3,17,17,17,17,17,17,17,17,17,17,17,17,17,17,17,17,17,17,17,17,17,17,17,17,17,17,17,17,17,17,17,17,17,17,17,17,17,17,17,17,17,17,17,17,17,17,19,19,19,19,19,19,19,0,0,0,0,0,0,0,17,17,17,17,17,17,19,4,19,19,19,19,19,19,0,0,0,9,9,0,17,17,17,17,17,17,19,19,11,11,11,11,11,11,11,11,11,11,11,11,11,11,11,11,11,11,11,11,11,11,19,19,19,19,19,0,0,0,0,0,0,0,0,0,11,11],[0,0,0,0,0,0,0,11,11,11,11,11,11,0,0,11,11,11,11,11,11,11,11,11,11,11,3,3,11,11,11,11,11,11,11,0,11,18,18,18,18,18,18,18,18,18,18,18,18,18,18,18,18,18,18,18,18,18,18,18,18,18,18,18,18,18,18,18,18,0,18,18,18,18,18,18,18,18,18,18,18,18,18,18,18,18,18,18,18,18,18,18,17,17,17,17,17,17,17,17,17,17,17,17,17,17,9,17,17,17,17,17,17,17,17,17,17,17,17,17,17,17,17,17,17,17,17,17,17,3,3,17,17,17,17,17,17,17,17,17,17,17,17,17,17,17,17,17,17,17,17,17,17,17,17,17,17,17,17,17,17,17,17,17,17,17,17,17,17,17,17,17,17,17,17,17,19,19,19,19,19,19,19,0,0,0,0,0,0,0,17,17,17,17,17,17,19,4,19,19,19,19,19,19,0,0,0,9,0,0,17,17,17,17,17,17,19,11,11,11,11,11,11,11,11,11,11,11,11,11,11,11,11,11,11,11,11,11,11,19,19,19,19,19,19,0,0,0,0,0,0,0,0,11,11,11],[0,0,0,0,0,0,11,11,11,11,11,11,11,11,0,11,11,11,11,11,11,11,11,11,11,11,11,3,11,11,11,11,11,11,0,11,11,18,18,18,18,18,18,18,18,18,18,18,18,18,18,18,18,18,18,18,18,18,18,18,18,18,18,18,18,18,18,18,18,0,18,18,18,18,18,18,18,18,18,18,18,18,18,18,18,18,18,18,18,18,18,17,17,17,17,17,17,17,17,17,17,17,17,17,17,17,9,17,17,17,17,17,17,17,17,17,17,17,17,17,17,17,17,17,17,17,17,17,17,17,3,3,17,17,17,17,17,17,17,17,17,17,17,17,17,17,17,17,17,17,17,17,17,17,17,17,17,17,17,17,17,17,17,17,17,17,17,17,17,17,17,17,17,17,17,17,19,19,19,19,19,19,19,0,0,0,0,0,0,0,17,17,17,17,17,17,19,4,19,19,19,19,19,0,0,0,0,9,0,0,17,17,17,17,17,17,17,11,11,11,11,11,11,11,11,11,11,11,11,11,11,11,11,11,11,11,11,11,11,19,19,19,19,19,19,19,0,0,0,0,0,0,0,11,11,11],[0,0,0,0,0,0,11,11,11,11,11,11,11,11,0,11,11,11,11,11,11,11,11,11,11,11,11,3,11,11,11,11,11,11,11,11,11,18,18,18,18,18,18,18,18,18,18,18,0,18,18,18,18,18,18,18,18,18,18,18,18,18,18,18,18,18,18,18,18,0,0,18,18,0,0,0,18,18,18,18,18,18,18,18,18,18,18,18,18,18,17,17,17,17,17,17,17,17,17,17,17,17,17,17,17,17,9,9,17,17,17,17,17,17,17,17,17,0,17,17,17,17,17,17,17,17,17,17,17,17,17,3,3,17,17,17,17,17,17,17,17,17,17,17,17,17,17,17,17,17,17,17,17,17,0,17,17,17,17,17,17,17,17,17,17,17,17,17,17,17,17,17,17,17,17,17,19,19,19,19,19,19,19,19,0,0,0,0,0,0,17,17,17,17,17,17,19,4,19,19,19,19,19,0,0,0,0,9,0,0,17,17,17,17,17,17,17,11,11,11,11,0,0,11,11,11,11,11,11,11,11,11,11,11,11,11,11,11,19,19,19,19,19,19,19,19,11,0,0,0,0,0,0,11,11,11],[0,0,0,0,0,0,11,11,11,11,11,11,11,11,0,11,11,11,11,11,11,11,11,11,11,11,11,3,11,11,11,11,11,0,11,11,11,18,18,18,18,18,18,18,18,18,18,18,0,18,18,18,18,18,18,0,18,18,18,18,18,18,18,18,18,18,18,18,18,18,18,0,0,18,18,18,18,18,18,18,18,18,18,18,18,18,18,18,18,17,17,17,17,0,0,17,17,17,17,17,17,17,17,17,17,17,0,9,0,17,17,17,17,17,17,17,17,17,0,17,17,17,17,17,17,17,17,17,17,17,17,17,3,3,17,17,17,17,17,17,17,17,17,17,17,17,17,17,17,17,17,17,17,17,0,0,17,17,17,17,17,17,17,17,17,17,17,0,0,17,17,17,17,17,17,17,19,19,19,19,19,19,19,19,0,0,0,0,0,17,17,17,17,17,17,17,19,4,19,19,19,19,0,0,0,0,9,9,0,0,17,17,17,17,17,17,11,11,11,0,0,11,11,11,11,11,11,11,11,11,11,11,11,0,11,11,11,0,0,0,19,19,19,11,11,11,11,11,11,0,0,0,0,11,11,11],[11,11,11,11,11,0,11,11,11,11,11,11,11,11,0,11,11,11,11,11,11,11,11,11,11,11,11,3,11,11,11,11,11,11,11,11,11,18,18,18,18,18,18,18,18,18,18,0,18,18,18,18,18,18,18,0,18,18,18,18,18,18,18,18,18,18,18,18,18,18,18
